# Généré par docs/showcase/scenes.mjs — ne pas éditer à la main.

# Socle : herbe, puis les volumes vidés en tranches (fill est limité à 32 768 blocs)
fill ~0 ~-3 ~0 ~72 ~-2 ~60 minecraft:dirt
fill ~0 ~-1 ~0 ~72 ~-1 ~60 minecraft:grass_block
fill ~0 ~0 ~0 ~72 ~5 ~60 minecraft:air
fill ~0 ~6 ~0 ~72 ~11 ~60 minecraft:air
fill ~0 ~12 ~0 ~72 ~17 ~60 minecraft:air
fill ~0 ~18 ~0 ~72 ~23 ~60 minecraft:air
fill ~0 ~24 ~0 ~72 ~29 ~60 minecraft:air
kill @e[type=!player,distance=..150]

# A. Halle : dalle, murs, piliers, fenêtres
fill ~4 ~-1 ~4 ~46 ~-1 ~28 minecraft:polished_andesite
fill ~5 ~-1 ~16 ~45 ~-1 ~16 minecraft:yellow_concrete
setblock ~5 ~-1 ~16 minecraft:black_concrete
setblock ~7 ~-1 ~16 minecraft:black_concrete
setblock ~9 ~-1 ~16 minecraft:black_concrete
setblock ~11 ~-1 ~16 minecraft:black_concrete
setblock ~13 ~-1 ~16 minecraft:black_concrete
setblock ~15 ~-1 ~16 minecraft:black_concrete
setblock ~17 ~-1 ~16 minecraft:black_concrete
setblock ~19 ~-1 ~16 minecraft:black_concrete
setblock ~21 ~-1 ~16 minecraft:black_concrete
setblock ~23 ~-1 ~16 minecraft:black_concrete
setblock ~25 ~-1 ~16 minecraft:black_concrete
setblock ~27 ~-1 ~16 minecraft:black_concrete
setblock ~29 ~-1 ~16 minecraft:black_concrete
setblock ~31 ~-1 ~16 minecraft:black_concrete
setblock ~33 ~-1 ~16 minecraft:black_concrete
setblock ~35 ~-1 ~16 minecraft:black_concrete
setblock ~37 ~-1 ~16 minecraft:black_concrete
setblock ~39 ~-1 ~16 minecraft:black_concrete
setblock ~41 ~-1 ~16 minecraft:black_concrete
setblock ~43 ~-1 ~16 minecraft:black_concrete
setblock ~45 ~-1 ~16 minecraft:black_concrete
fill ~5 ~-1 ~15 ~45 ~-1 ~15 mcwpaths:andesite_square_paving
fill ~5 ~-1 ~17 ~45 ~-1 ~17 mcwpaths:andesite_square_paving
fill ~4 ~0 ~4 ~46 ~1 ~4 minecraft:deepslate_tiles
fill ~4 ~2 ~4 ~46 ~8 ~4 minecraft:bricks
fill ~4 ~3 ~4 ~46 ~5 ~4 mcwwindows:metal_window2
fill ~4 ~0 ~28 ~46 ~1 ~28 minecraft:deepslate_tiles
fill ~4 ~2 ~28 ~46 ~8 ~28 minecraft:bricks
fill ~4 ~3 ~28 ~46 ~5 ~28 mcwwindows:metal_window2
fill ~4 ~0 ~4 ~4 ~1 ~28 minecraft:deepslate_tiles
fill ~4 ~2 ~4 ~4 ~8 ~28 minecraft:bricks
fill ~4 ~3 ~5 ~4 ~5 ~27 mcwwindows:metal_window2
fill ~46 ~0 ~4 ~46 ~1 ~28 minecraft:deepslate_tiles
fill ~46 ~2 ~4 ~46 ~8 ~28 minecraft:bricks
fill ~46 ~3 ~5 ~46 ~5 ~27 mcwwindows:metal_window2
fill ~4 ~0 ~4 ~4 ~9 ~4 minecraft:polished_deepslate
fill ~4 ~0 ~28 ~4 ~9 ~28 minecraft:polished_deepslate
fill ~10 ~0 ~4 ~10 ~9 ~4 minecraft:polished_deepslate
fill ~10 ~0 ~28 ~10 ~9 ~28 minecraft:polished_deepslate
fill ~16 ~0 ~4 ~16 ~9 ~4 minecraft:polished_deepslate
fill ~16 ~0 ~28 ~16 ~9 ~28 minecraft:polished_deepslate
fill ~22 ~0 ~4 ~22 ~9 ~4 minecraft:polished_deepslate
fill ~22 ~0 ~28 ~22 ~9 ~28 minecraft:polished_deepslate
fill ~28 ~0 ~4 ~28 ~9 ~4 minecraft:polished_deepslate
fill ~28 ~0 ~28 ~28 ~9 ~28 minecraft:polished_deepslate
fill ~34 ~0 ~4 ~34 ~9 ~4 minecraft:polished_deepslate
fill ~34 ~0 ~28 ~34 ~9 ~28 minecraft:polished_deepslate
fill ~40 ~0 ~4 ~40 ~9 ~4 minecraft:polished_deepslate
fill ~40 ~0 ~28 ~40 ~9 ~28 minecraft:polished_deepslate
fill ~46 ~0 ~4 ~46 ~9 ~4 minecraft:polished_deepslate
fill ~46 ~0 ~28 ~46 ~9 ~28 minecraft:polished_deepslate
fill ~4 ~0 ~4 ~4 ~9 ~4 minecraft:polished_deepslate
fill ~4 ~0 ~28 ~4 ~9 ~28 minecraft:polished_deepslate
fill ~46 ~0 ~4 ~46 ~9 ~4 minecraft:polished_deepslate
fill ~46 ~0 ~28 ~46 ~9 ~28 minecraft:polished_deepslate
fill ~46 ~0 ~13 ~46 ~4 ~19 minecraft:air
fill ~46 ~5 ~13 ~46 ~5 ~19 minecraft:polished_deepslate
fill ~22 ~0 ~28 ~26 ~3 ~28 minecraft:air

# A. Toit en sheds : pente en tuiles, face verticale vitrée tournée au nord
fill ~4 ~9 ~4 ~4 ~9 ~28 minecraft:deepslate_tile_stairs[facing=east]
fill ~5 ~9 ~4 ~5 ~9 ~28 minecraft:deepslate_tile_stairs[facing=east]
fill ~6 ~10 ~4 ~6 ~10 ~28 minecraft:deepslate_tile_stairs[facing=east]
fill ~6 ~9 ~4 ~6 ~9 ~28 minecraft:air
fill ~7 ~10 ~4 ~7 ~10 ~28 minecraft:deepslate_tile_stairs[facing=east]
fill ~7 ~9 ~4 ~7 ~9 ~28 minecraft:air
fill ~8 ~11 ~4 ~8 ~11 ~28 minecraft:deepslate_tile_stairs[facing=east]
fill ~8 ~9 ~4 ~8 ~10 ~28 minecraft:air
fill ~9 ~11 ~4 ~9 ~11 ~28 minecraft:deepslate_tile_stairs[facing=east]
fill ~9 ~9 ~4 ~9 ~10 ~28 minecraft:air
fill ~6 ~10 ~5 ~7 ~10 ~27 minecraft:glass
fill ~6 ~9 ~4 ~6 ~9 ~4 minecraft:bricks
fill ~6 ~9 ~28 ~6 ~9 ~28 minecraft:bricks
fill ~7 ~9 ~4 ~7 ~9 ~4 minecraft:bricks
fill ~7 ~9 ~28 ~7 ~9 ~28 minecraft:bricks
fill ~8 ~9 ~4 ~8 ~10 ~4 minecraft:bricks
fill ~8 ~9 ~28 ~8 ~10 ~28 minecraft:bricks
fill ~9 ~9 ~4 ~9 ~10 ~4 minecraft:bricks
fill ~9 ~9 ~28 ~9 ~10 ~28 minecraft:bricks
fill ~10 ~9 ~5 ~10 ~11 ~27 minecraft:glass_pane[east=false,west=false,north=true,south=true]
fill ~10 ~12 ~4 ~10 ~12 ~28 minecraft:polished_deepslate_slab
fill ~10 ~9 ~4 ~10 ~9 ~28 minecraft:deepslate_tile_stairs[facing=east]
fill ~11 ~9 ~4 ~11 ~9 ~28 minecraft:deepslate_tile_stairs[facing=east]
fill ~12 ~10 ~4 ~12 ~10 ~28 minecraft:deepslate_tile_stairs[facing=east]
fill ~12 ~9 ~4 ~12 ~9 ~28 minecraft:air
fill ~13 ~10 ~4 ~13 ~10 ~28 minecraft:deepslate_tile_stairs[facing=east]
fill ~13 ~9 ~4 ~13 ~9 ~28 minecraft:air
fill ~14 ~11 ~4 ~14 ~11 ~28 minecraft:deepslate_tile_stairs[facing=east]
fill ~14 ~9 ~4 ~14 ~10 ~28 minecraft:air
fill ~15 ~11 ~4 ~15 ~11 ~28 minecraft:deepslate_tile_stairs[facing=east]
fill ~15 ~9 ~4 ~15 ~10 ~28 minecraft:air
fill ~12 ~10 ~5 ~13 ~10 ~27 minecraft:glass
fill ~12 ~9 ~4 ~12 ~9 ~4 minecraft:bricks
fill ~12 ~9 ~28 ~12 ~9 ~28 minecraft:bricks
fill ~13 ~9 ~4 ~13 ~9 ~4 minecraft:bricks
fill ~13 ~9 ~28 ~13 ~9 ~28 minecraft:bricks
fill ~14 ~9 ~4 ~14 ~10 ~4 minecraft:bricks
fill ~14 ~9 ~28 ~14 ~10 ~28 minecraft:bricks
fill ~15 ~9 ~4 ~15 ~10 ~4 minecraft:bricks
fill ~15 ~9 ~28 ~15 ~10 ~28 minecraft:bricks
fill ~16 ~9 ~5 ~16 ~11 ~27 minecraft:glass_pane[east=false,west=false,north=true,south=true]
fill ~16 ~12 ~4 ~16 ~12 ~28 minecraft:polished_deepslate_slab
fill ~16 ~9 ~4 ~16 ~9 ~28 minecraft:deepslate_tile_stairs[facing=east]
fill ~17 ~9 ~4 ~17 ~9 ~28 minecraft:deepslate_tile_stairs[facing=east]
fill ~18 ~10 ~4 ~18 ~10 ~28 minecraft:deepslate_tile_stairs[facing=east]
fill ~18 ~9 ~4 ~18 ~9 ~28 minecraft:air
fill ~19 ~10 ~4 ~19 ~10 ~28 minecraft:deepslate_tile_stairs[facing=east]
fill ~19 ~9 ~4 ~19 ~9 ~28 minecraft:air
fill ~20 ~11 ~4 ~20 ~11 ~28 minecraft:deepslate_tile_stairs[facing=east]
fill ~20 ~9 ~4 ~20 ~10 ~28 minecraft:air
fill ~21 ~11 ~4 ~21 ~11 ~28 minecraft:deepslate_tile_stairs[facing=east]
fill ~21 ~9 ~4 ~21 ~10 ~28 minecraft:air
fill ~18 ~10 ~5 ~19 ~10 ~27 minecraft:glass
fill ~18 ~9 ~4 ~18 ~9 ~4 minecraft:bricks
fill ~18 ~9 ~28 ~18 ~9 ~28 minecraft:bricks
fill ~19 ~9 ~4 ~19 ~9 ~4 minecraft:bricks
fill ~19 ~9 ~28 ~19 ~9 ~28 minecraft:bricks
fill ~20 ~9 ~4 ~20 ~10 ~4 minecraft:bricks
fill ~20 ~9 ~28 ~20 ~10 ~28 minecraft:bricks
fill ~21 ~9 ~4 ~21 ~10 ~4 minecraft:bricks
fill ~21 ~9 ~28 ~21 ~10 ~28 minecraft:bricks
fill ~22 ~9 ~5 ~22 ~11 ~27 minecraft:glass_pane[east=false,west=false,north=true,south=true]
fill ~22 ~12 ~4 ~22 ~12 ~28 minecraft:polished_deepslate_slab
fill ~22 ~9 ~4 ~22 ~9 ~28 minecraft:deepslate_tile_stairs[facing=east]
fill ~23 ~9 ~4 ~23 ~9 ~28 minecraft:deepslate_tile_stairs[facing=east]
fill ~24 ~10 ~4 ~24 ~10 ~28 minecraft:deepslate_tile_stairs[facing=east]
fill ~24 ~9 ~4 ~24 ~9 ~28 minecraft:air
fill ~25 ~10 ~4 ~25 ~10 ~28 minecraft:deepslate_tile_stairs[facing=east]
fill ~25 ~9 ~4 ~25 ~9 ~28 minecraft:air
fill ~26 ~11 ~4 ~26 ~11 ~28 minecraft:deepslate_tile_stairs[facing=east]
fill ~26 ~9 ~4 ~26 ~10 ~28 minecraft:air
fill ~27 ~11 ~4 ~27 ~11 ~28 minecraft:deepslate_tile_stairs[facing=east]
fill ~27 ~9 ~4 ~27 ~10 ~28 minecraft:air
fill ~24 ~10 ~5 ~25 ~10 ~27 minecraft:glass
fill ~24 ~9 ~4 ~24 ~9 ~4 minecraft:bricks
fill ~24 ~9 ~28 ~24 ~9 ~28 minecraft:bricks
fill ~25 ~9 ~4 ~25 ~9 ~4 minecraft:bricks
fill ~25 ~9 ~28 ~25 ~9 ~28 minecraft:bricks
fill ~26 ~9 ~4 ~26 ~10 ~4 minecraft:bricks
fill ~26 ~9 ~28 ~26 ~10 ~28 minecraft:bricks
fill ~27 ~9 ~4 ~27 ~10 ~4 minecraft:bricks
fill ~27 ~9 ~28 ~27 ~10 ~28 minecraft:bricks
fill ~28 ~9 ~5 ~28 ~11 ~27 minecraft:glass_pane[east=false,west=false,north=true,south=true]
fill ~28 ~12 ~4 ~28 ~12 ~28 minecraft:polished_deepslate_slab
fill ~28 ~9 ~4 ~28 ~9 ~28 minecraft:deepslate_tile_stairs[facing=east]
fill ~29 ~9 ~4 ~29 ~9 ~28 minecraft:deepslate_tile_stairs[facing=east]
fill ~30 ~10 ~4 ~30 ~10 ~28 minecraft:deepslate_tile_stairs[facing=east]
fill ~30 ~9 ~4 ~30 ~9 ~28 minecraft:air
fill ~31 ~10 ~4 ~31 ~10 ~28 minecraft:deepslate_tile_stairs[facing=east]
fill ~31 ~9 ~4 ~31 ~9 ~28 minecraft:air
fill ~32 ~11 ~4 ~32 ~11 ~28 minecraft:deepslate_tile_stairs[facing=east]
fill ~32 ~9 ~4 ~32 ~10 ~28 minecraft:air
fill ~33 ~11 ~4 ~33 ~11 ~28 minecraft:deepslate_tile_stairs[facing=east]
fill ~33 ~9 ~4 ~33 ~10 ~28 minecraft:air
fill ~30 ~10 ~5 ~31 ~10 ~27 minecraft:glass
fill ~30 ~9 ~4 ~30 ~9 ~4 minecraft:bricks
fill ~30 ~9 ~28 ~30 ~9 ~28 minecraft:bricks
fill ~31 ~9 ~4 ~31 ~9 ~4 minecraft:bricks
fill ~31 ~9 ~28 ~31 ~9 ~28 minecraft:bricks
fill ~32 ~9 ~4 ~32 ~10 ~4 minecraft:bricks
fill ~32 ~9 ~28 ~32 ~10 ~28 minecraft:bricks
fill ~33 ~9 ~4 ~33 ~10 ~4 minecraft:bricks
fill ~33 ~9 ~28 ~33 ~10 ~28 minecraft:bricks
fill ~34 ~9 ~5 ~34 ~11 ~27 minecraft:glass_pane[east=false,west=false,north=true,south=true]
fill ~34 ~12 ~4 ~34 ~12 ~28 minecraft:polished_deepslate_slab
fill ~34 ~9 ~4 ~34 ~9 ~28 minecraft:deepslate_tile_stairs[facing=east]
fill ~35 ~9 ~4 ~35 ~9 ~28 minecraft:deepslate_tile_stairs[facing=east]
fill ~36 ~10 ~4 ~36 ~10 ~28 minecraft:deepslate_tile_stairs[facing=east]
fill ~36 ~9 ~4 ~36 ~9 ~28 minecraft:air
fill ~37 ~10 ~4 ~37 ~10 ~28 minecraft:deepslate_tile_stairs[facing=east]
fill ~37 ~9 ~4 ~37 ~9 ~28 minecraft:air
fill ~38 ~11 ~4 ~38 ~11 ~28 minecraft:deepslate_tile_stairs[facing=east]
fill ~38 ~9 ~4 ~38 ~10 ~28 minecraft:air
fill ~39 ~11 ~4 ~39 ~11 ~28 minecraft:deepslate_tile_stairs[facing=east]
fill ~39 ~9 ~4 ~39 ~10 ~28 minecraft:air
fill ~36 ~10 ~5 ~37 ~10 ~27 minecraft:glass
fill ~36 ~9 ~4 ~36 ~9 ~4 minecraft:bricks
fill ~36 ~9 ~28 ~36 ~9 ~28 minecraft:bricks
fill ~37 ~9 ~4 ~37 ~9 ~4 minecraft:bricks
fill ~37 ~9 ~28 ~37 ~9 ~28 minecraft:bricks
fill ~38 ~9 ~4 ~38 ~10 ~4 minecraft:bricks
fill ~38 ~9 ~28 ~38 ~10 ~28 minecraft:bricks
fill ~39 ~9 ~4 ~39 ~10 ~4 minecraft:bricks
fill ~39 ~9 ~28 ~39 ~10 ~28 minecraft:bricks
fill ~40 ~9 ~5 ~40 ~11 ~27 minecraft:glass_pane[east=false,west=false,north=true,south=true]
fill ~40 ~12 ~4 ~40 ~12 ~28 minecraft:polished_deepslate_slab
fill ~40 ~9 ~4 ~40 ~9 ~28 minecraft:deepslate_tile_stairs[facing=east]
fill ~41 ~9 ~4 ~41 ~9 ~28 minecraft:deepslate_tile_stairs[facing=east]
fill ~42 ~10 ~4 ~42 ~10 ~28 minecraft:deepslate_tile_stairs[facing=east]
fill ~42 ~9 ~4 ~42 ~9 ~28 minecraft:air
fill ~43 ~10 ~4 ~43 ~10 ~28 minecraft:deepslate_tile_stairs[facing=east]
fill ~43 ~9 ~4 ~43 ~9 ~28 minecraft:air
fill ~44 ~11 ~4 ~44 ~11 ~28 minecraft:deepslate_tile_stairs[facing=east]
fill ~44 ~9 ~4 ~44 ~10 ~28 minecraft:air
fill ~45 ~11 ~4 ~45 ~11 ~28 minecraft:deepslate_tile_stairs[facing=east]
fill ~45 ~9 ~4 ~45 ~10 ~28 minecraft:air
fill ~42 ~10 ~5 ~43 ~10 ~27 minecraft:glass
fill ~42 ~9 ~4 ~42 ~9 ~4 minecraft:bricks
fill ~42 ~9 ~28 ~42 ~9 ~28 minecraft:bricks
fill ~43 ~9 ~4 ~43 ~9 ~4 minecraft:bricks
fill ~43 ~9 ~28 ~43 ~9 ~28 minecraft:bricks
fill ~44 ~9 ~4 ~44 ~10 ~4 minecraft:bricks
fill ~44 ~9 ~28 ~44 ~10 ~28 minecraft:bricks
fill ~45 ~9 ~4 ~45 ~10 ~4 minecraft:bricks
fill ~45 ~9 ~28 ~45 ~10 ~28 minecraft:bricks
fill ~46 ~9 ~5 ~46 ~11 ~27 minecraft:glass_pane[east=false,west=false,north=true,south=true]
fill ~46 ~12 ~4 ~46 ~12 ~28 minecraft:polished_deepslate_slab

# A. Intérieur : passerelle le long du mur nord, éclairage suspendu
fill ~5 ~4 ~5 ~45 ~4 ~6 minecraft:polished_deepslate_slab[type=top]
fill ~5 ~5 ~7 ~45 ~5 ~7 minecraft:iron_bars[east=true,west=true]
fill ~10 ~0 ~7 ~10 ~4 ~7 minecraft:polished_deepslate_wall
fill ~16 ~0 ~7 ~16 ~4 ~7 minecraft:polished_deepslate_wall
fill ~22 ~0 ~7 ~22 ~4 ~7 minecraft:polished_deepslate_wall
fill ~28 ~0 ~7 ~28 ~4 ~7 minecraft:polished_deepslate_wall
fill ~34 ~0 ~7 ~34 ~4 ~7 minecraft:polished_deepslate_wall
fill ~40 ~0 ~7 ~40 ~4 ~7 minecraft:polished_deepslate_wall
fill ~7 ~4 ~10 ~7 ~8 ~10 minecraft:chain
setblock ~7 ~3 ~10 minecraft:lantern[hanging=true]
fill ~7 ~4 ~22 ~7 ~8 ~22 minecraft:chain
setblock ~7 ~3 ~22 minecraft:lantern[hanging=true]
fill ~13 ~4 ~10 ~13 ~8 ~10 minecraft:chain
setblock ~13 ~3 ~10 minecraft:lantern[hanging=true]
fill ~13 ~4 ~22 ~13 ~8 ~22 minecraft:chain
setblock ~13 ~3 ~22 minecraft:lantern[hanging=true]
fill ~19 ~4 ~10 ~19 ~8 ~10 minecraft:chain
setblock ~19 ~3 ~10 minecraft:lantern[hanging=true]
fill ~19 ~4 ~22 ~19 ~8 ~22 minecraft:chain
setblock ~19 ~3 ~22 minecraft:lantern[hanging=true]
fill ~25 ~4 ~10 ~25 ~8 ~10 minecraft:chain
setblock ~25 ~3 ~10 minecraft:lantern[hanging=true]
fill ~25 ~4 ~22 ~25 ~8 ~22 minecraft:chain
setblock ~25 ~3 ~22 minecraft:lantern[hanging=true]
fill ~31 ~4 ~10 ~31 ~8 ~10 minecraft:chain
setblock ~31 ~3 ~10 minecraft:lantern[hanging=true]
fill ~31 ~4 ~22 ~31 ~8 ~22 minecraft:chain
setblock ~31 ~3 ~22 minecraft:lantern[hanging=true]
fill ~37 ~4 ~10 ~37 ~8 ~10 minecraft:chain
setblock ~37 ~3 ~10 minecraft:lantern[hanging=true]
fill ~37 ~4 ~22 ~37 ~8 ~22 minecraft:chain
setblock ~37 ~3 ~22 minecraft:lantern[hanging=true]
fill ~43 ~4 ~10 ~43 ~8 ~10 minecraft:chain
setblock ~43 ~3 ~10 minecraft:lantern[hanging=true]
fill ~43 ~4 ~22 ~43 ~8 ~22 minecraft:chain
setblock ~43 ~3 ~22 minecraft:lantern[hanging=true]

# A. Stock à l'ouest : coffres de plaques, inserters à pile sur le bus A
setblock ~7 ~0 ~12 minecraft:chest[facing=south]{Items:[{Slot:0b,id:"factor_io:iron_plate",Count:64b},{Slot:1b,id:"factor_io:iron_plate",Count:64b},{Slot:2b,id:"factor_io:iron_plate",Count:64b},{Slot:3b,id:"factor_io:iron_plate",Count:64b},{Slot:4b,id:"factor_io:iron_plate",Count:64b},{Slot:5b,id:"factor_io:iron_plate",Count:64b},{Slot:6b,id:"factor_io:iron_plate",Count:64b},{Slot:7b,id:"factor_io:iron_plate",Count:64b},{Slot:8b,id:"factor_io:iron_plate",Count:64b},{Slot:9b,id:"factor_io:iron_plate",Count:64b},{Slot:10b,id:"factor_io:iron_plate",Count:64b},{Slot:11b,id:"factor_io:iron_plate",Count:64b},{Slot:12b,id:"factor_io:iron_plate",Count:64b},{Slot:13b,id:"factor_io:iron_plate",Count:64b},{Slot:14b,id:"factor_io:iron_plate",Count:64b},{Slot:15b,id:"factor_io:iron_plate",Count:64b},{Slot:16b,id:"factor_io:iron_plate",Count:64b},{Slot:17b,id:"factor_io:iron_plate",Count:64b},{Slot:18b,id:"factor_io:iron_plate",Count:64b},{Slot:19b,id:"factor_io:iron_plate",Count:64b},{Slot:20b,id:"factor_io:iron_plate",Count:64b},{Slot:21b,id:"factor_io:iron_plate",Count:64b},{Slot:22b,id:"factor_io:iron_plate",Count:64b},{Slot:23b,id:"factor_io:iron_plate",Count:64b},{Slot:24b,id:"factor_io:iron_plate",Count:64b},{Slot:25b,id:"factor_io:iron_plate",Count:64b},{Slot:26b,id:"factor_io:iron_plate",Count:64b}]}
setblock ~7 ~0 ~13 factor_io:stack_inserter[facing=south]
setblock ~9 ~0 ~12 minecraft:chest[facing=south]{Items:[{Slot:0b,id:"factor_io:iron_plate",Count:64b},{Slot:1b,id:"factor_io:iron_plate",Count:64b},{Slot:2b,id:"factor_io:iron_plate",Count:64b},{Slot:3b,id:"factor_io:iron_plate",Count:64b},{Slot:4b,id:"factor_io:iron_plate",Count:64b},{Slot:5b,id:"factor_io:iron_plate",Count:64b},{Slot:6b,id:"factor_io:iron_plate",Count:64b},{Slot:7b,id:"factor_io:iron_plate",Count:64b},{Slot:8b,id:"factor_io:iron_plate",Count:64b},{Slot:9b,id:"factor_io:iron_plate",Count:64b},{Slot:10b,id:"factor_io:iron_plate",Count:64b},{Slot:11b,id:"factor_io:iron_plate",Count:64b},{Slot:12b,id:"factor_io:iron_plate",Count:64b},{Slot:13b,id:"factor_io:iron_plate",Count:64b},{Slot:14b,id:"factor_io:iron_plate",Count:64b},{Slot:15b,id:"factor_io:iron_plate",Count:64b},{Slot:16b,id:"factor_io:iron_plate",Count:64b},{Slot:17b,id:"factor_io:iron_plate",Count:64b},{Slot:18b,id:"factor_io:iron_plate",Count:64b},{Slot:19b,id:"factor_io:iron_plate",Count:64b},{Slot:20b,id:"factor_io:iron_plate",Count:64b},{Slot:21b,id:"factor_io:iron_plate",Count:64b},{Slot:22b,id:"factor_io:iron_plate",Count:64b},{Slot:23b,id:"factor_io:iron_plate",Count:64b},{Slot:24b,id:"factor_io:iron_plate",Count:64b},{Slot:25b,id:"factor_io:iron_plate",Count:64b},{Slot:26b,id:"factor_io:iron_plate",Count:64b}]}
setblock ~9 ~0 ~13 factor_io:stack_inserter[facing=south]
setblock ~8 ~0 ~16 minecraft:chest[facing=north]{Items:[{Slot:0b,id:"factor_io:copper_plate",Count:64b},{Slot:1b,id:"factor_io:copper_plate",Count:64b},{Slot:2b,id:"factor_io:copper_plate",Count:64b},{Slot:3b,id:"factor_io:copper_plate",Count:64b},{Slot:4b,id:"factor_io:copper_plate",Count:64b},{Slot:5b,id:"factor_io:copper_plate",Count:64b},{Slot:6b,id:"factor_io:copper_plate",Count:64b},{Slot:7b,id:"factor_io:copper_plate",Count:64b},{Slot:8b,id:"factor_io:copper_plate",Count:64b},{Slot:9b,id:"factor_io:copper_plate",Count:64b},{Slot:10b,id:"factor_io:copper_plate",Count:64b},{Slot:11b,id:"factor_io:copper_plate",Count:64b},{Slot:12b,id:"factor_io:copper_plate",Count:64b},{Slot:13b,id:"factor_io:copper_plate",Count:64b},{Slot:14b,id:"factor_io:copper_plate",Count:64b},{Slot:15b,id:"factor_io:copper_plate",Count:64b},{Slot:16b,id:"factor_io:copper_plate",Count:64b},{Slot:17b,id:"factor_io:copper_plate",Count:64b},{Slot:18b,id:"factor_io:copper_plate",Count:64b},{Slot:19b,id:"factor_io:copper_plate",Count:64b},{Slot:20b,id:"factor_io:copper_plate",Count:64b},{Slot:21b,id:"factor_io:copper_plate",Count:64b},{Slot:22b,id:"factor_io:copper_plate",Count:64b},{Slot:23b,id:"factor_io:copper_plate",Count:64b},{Slot:24b,id:"factor_io:copper_plate",Count:64b},{Slot:25b,id:"factor_io:copper_plate",Count:64b},{Slot:26b,id:"factor_io:copper_plate",Count:64b}]}
setblock ~8 ~0 ~15 factor_io:stack_inserter[facing=north]
fill ~6 ~0 ~14 ~43 ~0 ~14 factor_io:transport_belt[facing=east]
setblock ~44 ~0 ~14 factor_io:inserter[facing=east]
setblock ~45 ~0 ~14 minecraft:barrel[facing=west]

# A. Rangée nord : engrenages et câbles
setblock ~14 ~0 ~11 factor_io:crafter_mk1[facing=south]{recipe:"factor_io:crafter/iron_gear_wheel"}
setblock ~14 ~0 ~13 factor_io:fast_inserter[facing=north]
setblock ~14 ~0 ~9 factor_io:fast_inserter[facing=north]
setblock ~21 ~0 ~11 factor_io:crafter_mk1[facing=south]{recipe:"factor_io:crafter/copper_cable"}
setblock ~21 ~0 ~13 factor_io:fast_inserter[facing=north]
setblock ~21 ~0 ~9 factor_io:fast_inserter[facing=north]
setblock ~28 ~0 ~11 factor_io:crafter_mk2[facing=south]{recipe:"factor_io:crafter/iron_gear_wheel",items:{Size:17,Items:[{Slot:13b,id:"factor_io:speed_module_2",Count:1b},{Slot:14b,id:"factor_io:speed_module_2",Count:1b}]}}
setblock ~28 ~0 ~13 factor_io:fast_inserter[facing=north]
setblock ~28 ~0 ~9 factor_io:fast_inserter[facing=north]
setblock ~35 ~0 ~11 factor_io:crafter_mk3[facing=south]{recipe:"factor_io:crafter/copper_cable",items:{Size:17,Items:[{Slot:13b,id:"factor_io:speed_module_3",Count:1b},{Slot:14b,id:"factor_io:speed_module_3",Count:1b},{Slot:15b,id:"factor_io:productivity_module_3",Count:1b},{Slot:16b,id:"factor_io:efficiency_module_3",Count:1b}]}}
setblock ~35 ~0 ~13 factor_io:stack_inserter[facing=north]
setblock ~35 ~0 ~9 factor_io:stack_inserter[facing=north]
fill ~10 ~0 ~8 ~39 ~0 ~8 factor_io:transport_belt[facing=east]

# A. Le convoyeur nord descend vers le bus B en franchissant le bus A sur deux rampes
setblock ~40 ~0 ~8 factor_io:transport_belt[facing=south]
fill ~40 ~0 ~9 ~40 ~0 ~12 factor_io:transport_belt[facing=south]
setblock ~40 ~0 ~13 factor_io:transport_belt_ramp[facing=south,flow=ramp_up]
setblock ~40 ~1 ~14 factor_io:transport_belt[facing=south]
setblock ~40 ~0 ~15 factor_io:transport_belt_ramp[facing=south,flow=ramp_down]
fill ~40 ~0 ~16 ~40 ~0 ~17 factor_io:transport_belt[facing=south]
setblock ~40 ~0 ~18 factor_io:transport_belt[facing=west]
fill ~7 ~0 ~18 ~39 ~0 ~18 factor_io:transport_belt[facing=west]
setblock ~6 ~0 ~18 factor_io:inserter[facing=west]
setblock ~5 ~0 ~18 minecraft:barrel[facing=east]
setblock ~38 ~0 ~16 minecraft:chest[facing=north]{Items:[{Slot:0b,id:"factor_io:iron_plate",Count:64b},{Slot:1b,id:"factor_io:iron_plate",Count:64b},{Slot:2b,id:"factor_io:iron_plate",Count:64b},{Slot:3b,id:"factor_io:iron_plate",Count:64b},{Slot:4b,id:"factor_io:iron_plate",Count:64b},{Slot:5b,id:"factor_io:iron_plate",Count:64b},{Slot:6b,id:"factor_io:iron_plate",Count:64b},{Slot:7b,id:"factor_io:iron_plate",Count:64b},{Slot:8b,id:"factor_io:iron_plate",Count:64b},{Slot:9b,id:"factor_io:iron_plate",Count:64b},{Slot:10b,id:"factor_io:iron_plate",Count:64b},{Slot:11b,id:"factor_io:iron_plate",Count:64b},{Slot:12b,id:"factor_io:iron_plate",Count:64b},{Slot:13b,id:"factor_io:iron_plate",Count:64b},{Slot:14b,id:"factor_io:iron_plate",Count:64b},{Slot:15b,id:"factor_io:iron_plate",Count:64b},{Slot:16b,id:"factor_io:iron_plate",Count:64b},{Slot:17b,id:"factor_io:iron_plate",Count:64b},{Slot:18b,id:"factor_io:iron_plate",Count:64b},{Slot:19b,id:"factor_io:iron_plate",Count:64b},{Slot:20b,id:"factor_io:iron_plate",Count:64b},{Slot:21b,id:"factor_io:iron_plate",Count:64b},{Slot:22b,id:"factor_io:iron_plate",Count:64b},{Slot:23b,id:"factor_io:iron_plate",Count:64b},{Slot:24b,id:"factor_io:iron_plate",Count:64b},{Slot:25b,id:"factor_io:iron_plate",Count:64b},{Slot:26b,id:"factor_io:iron_plate",Count:64b}]}
setblock ~38 ~0 ~17 factor_io:fast_inserter[facing=south]

# A. Rangée sud : circuits électroniques
setblock ~14 ~0 ~21 factor_io:crafter_mk2[facing=north]{recipe:"factor_io:crafter/electronic_circuit"}
setblock ~14 ~0 ~19 factor_io:fast_inserter[facing=south]
setblock ~14 ~0 ~23 factor_io:fast_inserter[facing=south]
setblock ~21 ~0 ~21 factor_io:crafter_mk2[facing=north]{recipe:"factor_io:crafter/electronic_circuit",items:{Size:17,Items:[{Slot:13b,id:"factor_io:speed_module",Count:1b},{Slot:14b,id:"factor_io:speed_module",Count:1b}]}}
setblock ~21 ~0 ~19 factor_io:fast_inserter[facing=south]
setblock ~21 ~0 ~23 factor_io:fast_inserter[facing=south]
setblock ~28 ~0 ~21 factor_io:crafter_mk3[facing=north]{recipe:"factor_io:crafter/electronic_circuit",items:{Size:17,Items:[{Slot:13b,id:"factor_io:speed_module_3",Count:1b},{Slot:14b,id:"factor_io:speed_module_3",Count:1b},{Slot:15b,id:"factor_io:speed_module_3",Count:1b},{Slot:16b,id:"factor_io:speed_module_3",Count:1b}]}}
setblock ~28 ~0 ~19 factor_io:fast_inserter[facing=south]
setblock ~28 ~0 ~23 factor_io:fast_inserter[facing=south]
fill ~10 ~0 ~24 ~41 ~0 ~24 factor_io:transport_belt[facing=east]
setblock ~42 ~0 ~24 factor_io:inserter[facing=east]
setblock ~43 ~0 ~24 minecraft:barrel[facing=west]
setblock ~36 ~0 ~21 minecraft:crafting_table
setblock ~37 ~0 ~21 minecraft:smithing_table
setblock ~36 ~0 ~22 minecraft:barrel[facing=up]
setblock ~37 ~0 ~22 minecraft:barrel[facing=up]
setblock ~36 ~1 ~22 minecraft:barrel[facing=up]
setblock ~38 ~0 ~22 supplementaries:sack

# B. Station de tri, au sud de la halle
fill ~6 ~-1 ~36 ~43 ~-1 ~44 mcwpaths:andesite_running_bond
fill ~22 ~-1 ~29 ~26 ~-1 ~35 mcwpaths:andesite_running_bond_path
setblock ~7 ~0 ~38 minecraft:chest[facing=south]{Items:[{Slot:0b,id:"factor_io:iron_plate",Count:64b},{Slot:1b,id:"factor_io:iron_plate",Count:64b},{Slot:2b,id:"factor_io:iron_plate",Count:64b},{Slot:3b,id:"factor_io:iron_plate",Count:64b},{Slot:4b,id:"factor_io:iron_plate",Count:64b},{Slot:5b,id:"factor_io:iron_plate",Count:64b},{Slot:6b,id:"factor_io:copper_plate",Count:64b},{Slot:7b,id:"factor_io:copper_plate",Count:64b},{Slot:8b,id:"factor_io:copper_plate",Count:64b},{Slot:9b,id:"factor_io:copper_plate",Count:64b},{Slot:10b,id:"factor_io:copper_plate",Count:64b},{Slot:11b,id:"factor_io:copper_plate",Count:64b},{Slot:12b,id:"factor_io:iron_gear_wheel",Count:64b},{Slot:13b,id:"factor_io:iron_gear_wheel",Count:64b},{Slot:14b,id:"factor_io:iron_gear_wheel",Count:64b},{Slot:15b,id:"factor_io:iron_gear_wheel",Count:64b},{Slot:16b,id:"factor_io:iron_gear_wheel",Count:64b},{Slot:17b,id:"factor_io:electronic_circuit",Count:64b},{Slot:18b,id:"factor_io:electronic_circuit",Count:64b},{Slot:19b,id:"factor_io:electronic_circuit",Count:64b},{Slot:20b,id:"factor_io:electronic_circuit",Count:64b},{Slot:21b,id:"factor_io:electronic_circuit",Count:64b},{Slot:22b,id:"minecraft:coal",Count:64b},{Slot:23b,id:"minecraft:coal",Count:64b},{Slot:24b,id:"minecraft:coal",Count:64b},{Slot:25b,id:"minecraft:coal",Count:64b},{Slot:26b,id:"minecraft:coal",Count:64b}]}
setblock ~7 ~0 ~39 factor_io:stack_inserter[facing=south]
setblock ~7 ~0 ~40 factor_io:fast_transport_belt[facing=east]
fill ~8 ~0 ~40 ~40 ~0 ~40 factor_io:fast_transport_belt[facing=east]
setblock ~41 ~0 ~40 factor_io:inserter[facing=east]
setblock ~42 ~0 ~40 minecraft:barrel[facing=west]
setblock ~10 ~0 ~41 factor_io:burner_inserter[facing=south]{inserterFuelLevel:4000}
setblock ~10 ~0 ~42 minecraft:barrel[facing=north]
setblock ~14 ~0 ~41 factor_io:inserter[facing=south]
setblock ~14 ~0 ~42 minecraft:barrel[facing=north]
setblock ~18 ~0 ~41 factor_io:long_handed_inserter[facing=south]
setblock ~18 ~-1 ~42 minecraft:polished_andesite
setblock ~18 ~0 ~43 minecraft:barrel[facing=north]
setblock ~22 ~0 ~41 factor_io:fast_inserter[facing=south]
setblock ~22 ~0 ~42 minecraft:barrel[facing=north]
setblock ~26 ~0 ~41 factor_io:filter_inserter[facing=south]{inserterInventory:{Size:8,Items:[{Slot:1b,id:"factor_io:copper_plate",Count:1b}]}}
setblock ~26 ~0 ~42 minecraft:barrel[facing=north]
setblock ~30 ~0 ~41 factor_io:stack_inserter[facing=south]
setblock ~30 ~0 ~42 minecraft:barrel[facing=north]
setblock ~34 ~0 ~41 factor_io:stack_filter_inserter[facing=south]{inserterInventory:{Size:10,Items:[{Slot:1b,id:"factor_io:electronic_circuit",Count:1b}]}}
setblock ~34 ~0 ~42 minecraft:barrel[facing=north]
fill ~6 ~0 ~44 ~43 ~0 ~44 mcwfences:panelled_metal_fence
setblock ~8 ~0 ~37 mcwlights:double_street_lamp
setblock ~16 ~0 ~37 mcwlights:double_street_lamp
setblock ~24 ~0 ~37 mcwlights:double_street_lamp
setblock ~32 ~0 ~37 mcwlights:double_street_lamp
setblock ~40 ~0 ~37 mcwlights:double_street_lamp

# C. Bus extérieur : trois paliers, une rampe qui enjambe une voie
fill ~47 ~-1 ~12 ~68 ~-1 ~20 mcwpaths:andesite_square_paving
setblock ~47 ~0 ~14 minecraft:chest[facing=east]{Items:[{Slot:0b,id:"factor_io:iron_gear_wheel",Count:64b},{Slot:1b,id:"factor_io:iron_gear_wheel",Count:64b},{Slot:2b,id:"factor_io:iron_gear_wheel",Count:64b},{Slot:3b,id:"factor_io:iron_gear_wheel",Count:64b},{Slot:4b,id:"factor_io:iron_gear_wheel",Count:64b},{Slot:5b,id:"factor_io:iron_gear_wheel",Count:64b},{Slot:6b,id:"factor_io:iron_gear_wheel",Count:64b},{Slot:7b,id:"factor_io:iron_gear_wheel",Count:64b},{Slot:8b,id:"factor_io:iron_gear_wheel",Count:64b},{Slot:9b,id:"factor_io:iron_gear_wheel",Count:64b},{Slot:10b,id:"factor_io:iron_gear_wheel",Count:64b},{Slot:11b,id:"factor_io:iron_gear_wheel",Count:64b},{Slot:12b,id:"factor_io:iron_gear_wheel",Count:64b},{Slot:13b,id:"factor_io:iron_gear_wheel",Count:64b},{Slot:14b,id:"factor_io:iron_gear_wheel",Count:64b},{Slot:15b,id:"factor_io:iron_gear_wheel",Count:64b},{Slot:16b,id:"factor_io:iron_gear_wheel",Count:64b},{Slot:17b,id:"factor_io:iron_gear_wheel",Count:64b},{Slot:18b,id:"factor_io:iron_gear_wheel",Count:64b},{Slot:19b,id:"factor_io:iron_gear_wheel",Count:64b},{Slot:20b,id:"factor_io:iron_gear_wheel",Count:64b},{Slot:21b,id:"factor_io:iron_gear_wheel",Count:64b},{Slot:22b,id:"factor_io:iron_gear_wheel",Count:64b},{Slot:23b,id:"factor_io:iron_gear_wheel",Count:64b},{Slot:24b,id:"factor_io:iron_gear_wheel",Count:64b},{Slot:25b,id:"factor_io:iron_gear_wheel",Count:64b},{Slot:26b,id:"factor_io:iron_gear_wheel",Count:64b}]}
setblock ~48 ~0 ~14 factor_io:stack_inserter[facing=east]
fill ~49 ~0 ~14 ~66 ~0 ~14 factor_io:transport_belt[facing=east]
setblock ~67 ~0 ~14 factor_io:inserter[facing=east]
setblock ~68 ~0 ~14 minecraft:barrel[facing=west]
setblock ~47 ~0 ~16 minecraft:chest[facing=east]{Items:[{Slot:0b,id:"factor_io:copper_cable",Count:64b},{Slot:1b,id:"factor_io:copper_cable",Count:64b},{Slot:2b,id:"factor_io:copper_cable",Count:64b},{Slot:3b,id:"factor_io:copper_cable",Count:64b},{Slot:4b,id:"factor_io:copper_cable",Count:64b},{Slot:5b,id:"factor_io:copper_cable",Count:64b},{Slot:6b,id:"factor_io:copper_cable",Count:64b},{Slot:7b,id:"factor_io:copper_cable",Count:64b},{Slot:8b,id:"factor_io:copper_cable",Count:64b},{Slot:9b,id:"factor_io:copper_cable",Count:64b},{Slot:10b,id:"factor_io:copper_cable",Count:64b},{Slot:11b,id:"factor_io:copper_cable",Count:64b},{Slot:12b,id:"factor_io:copper_cable",Count:64b},{Slot:13b,id:"factor_io:copper_cable",Count:64b},{Slot:14b,id:"factor_io:copper_cable",Count:64b},{Slot:15b,id:"factor_io:copper_cable",Count:64b},{Slot:16b,id:"factor_io:copper_cable",Count:64b},{Slot:17b,id:"factor_io:copper_cable",Count:64b},{Slot:18b,id:"factor_io:copper_cable",Count:64b},{Slot:19b,id:"factor_io:copper_cable",Count:64b},{Slot:20b,id:"factor_io:copper_cable",Count:64b},{Slot:21b,id:"factor_io:copper_cable",Count:64b},{Slot:22b,id:"factor_io:copper_cable",Count:64b},{Slot:23b,id:"factor_io:copper_cable",Count:64b},{Slot:24b,id:"factor_io:copper_cable",Count:64b},{Slot:25b,id:"factor_io:copper_cable",Count:64b},{Slot:26b,id:"factor_io:copper_cable",Count:64b}]}
setblock ~48 ~0 ~16 factor_io:stack_inserter[facing=east]
fill ~49 ~0 ~16 ~66 ~0 ~16 factor_io:fast_transport_belt[facing=east]
setblock ~67 ~0 ~16 factor_io:inserter[facing=east]
setblock ~68 ~0 ~16 minecraft:barrel[facing=west]
setblock ~47 ~0 ~18 minecraft:chest[facing=east]{Items:[{Slot:0b,id:"factor_io:iron_plate",Count:64b},{Slot:1b,id:"factor_io:iron_plate",Count:64b},{Slot:2b,id:"factor_io:iron_plate",Count:64b},{Slot:3b,id:"factor_io:iron_plate",Count:64b},{Slot:4b,id:"factor_io:iron_plate",Count:64b},{Slot:5b,id:"factor_io:iron_plate",Count:64b},{Slot:6b,id:"factor_io:iron_plate",Count:64b},{Slot:7b,id:"factor_io:iron_plate",Count:64b},{Slot:8b,id:"factor_io:iron_plate",Count:64b},{Slot:9b,id:"factor_io:iron_plate",Count:64b},{Slot:10b,id:"factor_io:iron_plate",Count:64b},{Slot:11b,id:"factor_io:iron_plate",Count:64b},{Slot:12b,id:"factor_io:iron_plate",Count:64b},{Slot:13b,id:"factor_io:iron_plate",Count:64b},{Slot:14b,id:"factor_io:iron_plate",Count:64b},{Slot:15b,id:"factor_io:iron_plate",Count:64b},{Slot:16b,id:"factor_io:iron_plate",Count:64b},{Slot:17b,id:"factor_io:iron_plate",Count:64b},{Slot:18b,id:"factor_io:iron_plate",Count:64b},{Slot:19b,id:"factor_io:iron_plate",Count:64b},{Slot:20b,id:"factor_io:iron_plate",Count:64b},{Slot:21b,id:"factor_io:iron_plate",Count:64b},{Slot:22b,id:"factor_io:iron_plate",Count:64b},{Slot:23b,id:"factor_io:iron_plate",Count:64b},{Slot:24b,id:"factor_io:iron_plate",Count:64b},{Slot:25b,id:"factor_io:iron_plate",Count:64b},{Slot:26b,id:"factor_io:iron_plate",Count:64b}]}
setblock ~48 ~0 ~18 factor_io:stack_inserter[facing=east]
fill ~49 ~0 ~18 ~66 ~0 ~18 factor_io:express_transport_belt[facing=east]
setblock ~67 ~0 ~18 factor_io:inserter[facing=east]
setblock ~68 ~0 ~18 minecraft:barrel[facing=west]
setblock ~58 ~0 ~9 minecraft:chest[facing=south]{Items:[{Slot:0b,id:"factor_io:copper_plate",Count:64b},{Slot:1b,id:"factor_io:copper_plate",Count:64b},{Slot:2b,id:"factor_io:copper_plate",Count:64b},{Slot:3b,id:"factor_io:copper_plate",Count:64b},{Slot:4b,id:"factor_io:copper_plate",Count:64b},{Slot:5b,id:"factor_io:copper_plate",Count:64b},{Slot:6b,id:"factor_io:copper_plate",Count:64b},{Slot:7b,id:"factor_io:copper_plate",Count:64b},{Slot:8b,id:"factor_io:copper_plate",Count:64b},{Slot:9b,id:"factor_io:copper_plate",Count:64b},{Slot:10b,id:"factor_io:copper_plate",Count:64b},{Slot:11b,id:"factor_io:copper_plate",Count:64b},{Slot:12b,id:"factor_io:copper_plate",Count:64b},{Slot:13b,id:"factor_io:copper_plate",Count:64b},{Slot:14b,id:"factor_io:copper_plate",Count:64b},{Slot:15b,id:"factor_io:copper_plate",Count:64b},{Slot:16b,id:"factor_io:copper_plate",Count:64b},{Slot:17b,id:"factor_io:copper_plate",Count:64b},{Slot:18b,id:"factor_io:copper_plate",Count:64b},{Slot:19b,id:"factor_io:copper_plate",Count:64b},{Slot:20b,id:"factor_io:copper_plate",Count:64b},{Slot:21b,id:"factor_io:copper_plate",Count:64b},{Slot:22b,id:"factor_io:copper_plate",Count:64b},{Slot:23b,id:"factor_io:copper_plate",Count:64b},{Slot:24b,id:"factor_io:copper_plate",Count:64b},{Slot:25b,id:"factor_io:copper_plate",Count:64b},{Slot:26b,id:"factor_io:copper_plate",Count:64b}]}
setblock ~58 ~0 ~10 factor_io:fast_inserter[facing=south]
fill ~58 ~0 ~11 ~58 ~0 ~12 factor_io:fast_transport_belt[facing=south]
setblock ~58 ~0 ~13 factor_io:fast_transport_belt_ramp[facing=south,flow=ramp_up]
fill ~58 ~1 ~14 ~58 ~1 ~18 factor_io:fast_transport_belt[facing=south]
setblock ~58 ~0 ~19 factor_io:fast_transport_belt_ramp[facing=south,flow=ramp_down]
fill ~58 ~0 ~20 ~58 ~0 ~22 factor_io:fast_transport_belt[facing=south]
setblock ~58 ~0 ~23 factor_io:inserter[facing=south]
setblock ~58 ~0 ~24 minecraft:barrel[facing=north]
setblock ~47 ~0 ~21 mcwlights:classic_street_lamp
setblock ~54 ~0 ~21 mcwlights:classic_street_lamp
setblock ~61 ~0 ~21 mcwlights:classic_street_lamp
setblock ~68 ~0 ~21 mcwlights:classic_street_lamp

# D. Abords : arbres replantés, chemins
execute positioned ~-6 ~0 ~10 run place feature minecraft:fancy_oak
execute positioned ~-8 ~0 ~34 run place feature minecraft:oak
execute positioned ~2 ~0 ~54 run place feature minecraft:birch
execute positioned ~30 ~0 ~58 run place feature minecraft:fancy_oak
execute positioned ~52 ~0 ~50 run place feature minecraft:oak
execute positioned ~70 ~0 ~40 run place feature minecraft:birch
execute positioned ~76 ~0 ~6 run place feature minecraft:fancy_oak
execute positioned ~60 ~0 ~-6 run place feature minecraft:oak
execute positioned ~20 ~0 ~-8 run place feature minecraft:birch
